<?xml version="1.0" ?>
<!-- =================================================================================== -->
<!-- |    This document was autogenerated by xacro from /home/sudharsan/Documents/notspot_sim_py/src/notspot_description/urdf/notspot.xacro | -->
<!-- |    EDITING THIS FILE BY HAND IS NOT RECOMMENDED                                 | -->
<!-- =================================================================================== -->
<!-- =================================================================================== -->
<!-- |    This document was autogenerated by xacro from /home/sudharsan/Documents/notspot_sim_py/src/notspot_description/urdf/notspot.xacro | -->
<!-- |    EDITING THIS FILE BY HAND IS NOT RECOMMENDED                                 | -->
<!-- =================================================================================== -->
<robot name="notspot">
  <!-- base_link -->
  <link name="base_link">
    <visual>
      <geometry>
        <mesh filename="/home/sudharsan/Documents/notspot_sim_py/src/notspot_description/meshes/dae_files/body_obj.dae"/>
      </geometry>
    </visual>
    <inertial>
      <origin rpy="0.000 0.000 0.000" xyz="0.000 0.000 0.000"/>
      <mass value="0.81700"/>
       <inertia
        izz="0.00058474"
        ixy="-1.0045E-06"
        ixz="1.0886E-08"
        iyy="0.00029699"
        iyz="3.2027E-08"
        ixx="0.00063853" />
    </inertial>
    <collision>
      <origin rpy="0.000 0.000 0.000" xyz="0.000 0.000 0.000"/>
      <geometry>
        <mesh filename="/home/sudharsan/Documents/notspot_sim_py/src/notspot_description/meshes/dae_files/body_obj.dae"/>
      </geometry>
    </collision>
  </link>
<!-- <link name="hip_fl_ref">
	    <visual>
	      <geometry>
		<box size="0.002 0.002 0.002"/>
	      </geometry>
	    </visual>
	    <inertial>
	      <origin rpy="0.000 0.000 0.000" xyz="0.000 0.000 0.000"/>
	      <mass value="0.002"/>
	      <inertia izz="0.00020" ixy="0.00020" ixz="0.00020" iyy="0.00020" iyz="0.00020" ixx="0.00020"/>
	    </inertial>
	    <collision>
	      <origin rpy="0.000 0.000 0.000" xyz="0.000 0.000 0.000"/>
	      <geometry>
		<box size="0.002 0.002 0.002"/>
	      </geometry>
	    </collision>
	  </link>
	  <link name="hip_fr_ref">
	    <visual>
	      <geometry>
		<box size="0.002 0.002 0.002"/>
	      </geometry>
	    </visual>
	    <inertial>
	      <origin rpy="0.000 0.000 0.000" xyz="0.000 0.000 0.000"/>
	      <mass value="0.002"/>
	      <inertia izz="0.00020" ixy="0.00020" ixz="0.00020" iyy="0.00020" iyz="0.00020" ixx="0.00020"/>
	    </inertial>
	    <collision>
	      <origin rpy="0.000 0.000 0.000" xyz="0.000 0.000 0.000"/>
	      <geometry>
		<box size="0.002 0.002 0.002"/>
	      </geometry>
	    </collision>
	  </link>
	  <link name="hip_bl_ref">
	    <visual>
	      <geometry>
		<box size="0.002 0.002 0.002"/>
	      </geometry>
	    </visual>
	    <inertial>
	      <origin rpy="0.000 0.000 0.000" xyz="0.000 0.000 0.000"/>
	      <mass value="0.002"/>
	      <inertia izz="0.00020" ixy="0.00020" ixz="0.00020" iyy="0.00020" iyz="0.00020" ixx="0.00020"/>
	    </inertial>
	    <collision>
	      <origin rpy="0.000 0.000 0.000" xyz="0.000 0.000 0.000"/>
	      <geometry>
		<box size="0.002 0.002 0.002"/>
	      </geometry>
	    </collision>
	  </link>
	  <link name="hip_br_ref">
	    <visual>
	      <geometry>
		<box size="0.002 0.002 0.002"/>
	      </geometry>
	    </visual>
	    <inertial>
	      <origin rpy="0.000 0.000 0.000" xyz="0.000 0.000 0.000"/>
	      <mass value="0.002"/>
	      <inertia izz="0.00020" ixy="0.00020" ixz="0.00020" iyy="0.00020" iyz="0.00020" ixx="0.00020"/>
	    </inertial>
	    <collision>
	      <origin rpy="0.000 0.000 0.000" xyz="0.000 0.000 0.000"/>
	      <geometry>
		<box size="0.002 0.002 0.002"/>
	      </geometry>
	    </collision>
	  </link> -->

	  <!-- FL1 -->
	  <link name="FL1">
	    <visual>
	      <geometry>
		<mesh filename="/home/sudharsan/Documents/notspot_sim_py/src/notspot_description/meshes/dae_files/FL1_obj.dae"/>
	      </geometry>
	    </visual>
	    <inertial>
	      <origin rpy="0.000 0.000 0.000" xyz="-0.011124 -0.0032814 0.00014476"/>
	      <mass value="0.233"/>
	       <inertia
        izz="4.4732E-05"
        ixy="1.0746E-05"
        ixz="1.7651E-07"
        iyy="4.3482E-05"
        iyz="-7.8105E-08"
        ixx="6.8645E-05" />
	    </inertial>
	    <collision>
	      <origin rpy="0.000 0.000 0.000" xyz="0.000 0.000 0.000"/>
	      <geometry>
		<mesh filename="/home/sudharsan/Documents/notspot_sim_py/src/notspot_description/meshes/dae_files/FL1_obj.dae"/>
	      </geometry>
	    </collision>
	  </link>
	  <!-- FR1 -->
	  <link name="FR1">
	    <visual>
	      <geometry>
		<mesh filename="/home/sudharsan/Documents/notspot_sim_py/src/notspot_description/meshes/dae_files/FR1_obj.dae"/>
	      </geometry>
	    </visual>
	    <inertial>
	      <origin rpy="0.000 0.00 0.000" xyz="0.011092 -0.0032719 0.00019267"/>
	      <mass value="0.233"/>
	        <inertia
        izz="4.474E-05"
        ixy="1.0746E-05"
        ixz="-1.7651E-07"
        iyy="4.3489E-05"
        iyz="-7.8105E-08"
        ixx="6.8646E-05" />
	    </inertial>
	    <collision>
	      <origin rpy="0.000 0.000 0.000" xyz="0.000 0.000 0.000"/>
	      <geometry>
		<mesh filename="/home/sudharsan/Documents/notspot_sim_py/src/notspot_description/meshes/dae_files/FR1_obj.dae"/>
	      </geometry>
	    </collision>
	  </link>
	  <!-- RL1 -->
	  <link name="RL1">
	    <visual>
	      <geometry>
		<mesh filename="/home/sudharsan/Documents/notspot_sim_py/src/notspot_description/meshes/dae_files/RL1_obj.dae"/>
	      </geometry>0
	    </visual>
	    <inertial>
	      <origin rpy="0.000 0.000 0.000" xyz="0.000 0.000 0.000"/>
	      <mass value="0.233"/>
	       <inertia
        izz="4.474E-05"
        ixy="1.0746E-05"
        ixz="-1.7651E-07"
        iyy="4.3489E-05"
        iyz="7.8105E-08"
        ixx="6.8646E-05" />
	    </inertial>
	    <collision>
	      <origin rpy="0.000 0.000 0.000" xyz="0.000 0.000 0.000"/>
	      <geometry>
		<mesh filename="/home/sudharsan/Documents/notspot_sim_py/src/notspot_description/meshes/dae_files/RL1_obj.dae"/>
	      </geometry>
	    </collision>
	  </link>
	  <!-- RR1 -->
	  <link name="RR1">
	    <visual>
	      <geometry>
		<mesh filename="/home/sudharsan/Documents/notspot_sim_py/src/notspot_description/meshes/dae_files/RR1_obj.dae"/>
	      </geometry>
	    </visual>
	    <inertial>
	      <origin rpy="0.000 0.000 0.000" xyz="0.000 0.000 0.000"/>
	      <mass value="0.233"/>
	      <inertia
        izz="4.474E-05"
        ixy="-1.0746E-05"
        ixz="1.7651E-07"
        iyy="4.3489E-05"
        iyz="7.8105E-08"
        ixx="6.8646E-05" />
	    </inertial>
	    <collision>
	      <origin rpy="0.000 0.000 0.000" xyz="0.000 0.000 0.000"/>
	      <geometry>
		<mesh filename="/home/sudharsan/Documents/notspot_sim_py/src/notspot_description/meshes/dae_files/RR1_obj.dae"/>
	      </geometry>
	    </collision>
	  </link>
	  <!-- FL2 -->
	  <link name="FL2">
	    <visual>
	      <geometry>
		<mesh filename="/home/sudharsan/Documents/notspot_sim_py/src/notspot_description/meshes/dae_files/L2_obj.dae"/>
	      </geometry>
	    </visual>
	    <inertial>
	      <origin rpy="0.000 0.000 0.000" xyz="-0.005 0.000 -0.060"/>
	      <mass value="0.184"/>
	     <inertia
        izz="2.365E-05"
        ixy="-5.3771E-07"
        ixz="1.6144E-06"
        iyy="0.00010469"
        iyz="-8.306E-08"
        ixx="0.00011187" />
	    </inertial>
	    <collision>
	      <origin rpy="0.000 0.000 0.000" xyz="0.000 0.000 0.000"/>
	      <geometry>
		<mesh filename="/home/sudharsan/Documents/notspot_sim_py/src/notspot_description/meshes/dae_files/L2_obj.dae"/>
	      </geometry>
	    </collision>
	  </link>
	  <!-- FR2 -->
	  <link name="FR2">
	    <visual>
	      <geometry>
		<mesh filename="/home/sudharsan/Documents/notspot_sim_py/src/notspot_description/meshes/dae_files/R2_obj.dae"/>
	      </geometry>
	    </visual>
	    <inertial>
	      <origin rpy="0.000 0.000 0.000" xyz="-0.005 0.000 -0.060"/>
	      <mass value="0.184"/>
	      <inertia
        izz="2.365E-05"
        ixy="-5.3771E-07"
        ixz="-1.6144E-06"
        iyy="0.00010469"
        iyz="8.3059E-08"
        ixx="0.00011187" />
	    </inertial>
	    <collision>
	      <origin rpy="0.000 0.000 0.000" xyz="0.000 0.000 0.000"/>
	      <geometry>
		<mesh filename="/home/sudharsan/Documents/notspot_sim_py/src/notspot_description/meshes/dae_files/R2_obj.dae"/>
	      </geometry>
	    </collision>
	  </link>
	  <!-- RL2 -->
	  <link name="RL2">
	    <visual>
	      <geometry>
		<mesh filename="/home/sudharsan/Documents/notspot_sim_py/src/notspot_description/meshes/dae_files/L2_obj.dae"/>
	      </geometry>
	    </visual>
	    <inertial>
	      <origin rpy="0.000 0.000 0.000" xyz="-0.005 0.000 -0.060"/>
	      <mass value="0.184"/>
	       <inertia
        izz="2.365E-05"
        ixy="-5.3771E-07"
        ixz="1.6144E-06"
        iyy="0.00010469"
        iyz="-8.306E-08"
        ixx="0.00011187" />
	    </inertial>
	    <collision>
	      <origin rpy="0.000 0.000 0.000" xyz="0.000 0.000 0.000"/>
	      <geometry>
		<mesh filename="/home/sudharsan/Documents/notspot_sim_py/src/notspot_description/meshes/dae_files/L2_obj.dae"/>
	      </geometry>
	    </collision>
	  </link>
	  <!-- RR2 -->
	  <link name="RR2">
	    <visual>
	      <geometry>
		<mesh filename="/home/sudharsan/Documents/notspot_sim_py/src/notspot_description/meshes/dae_files/R2_obj.dae"/>
	      </geometry>
	    </visual>
	    <inertial>
	      <origin rpy="0.000 0.000 0.000" xyz="-0.005 0.000 -0.060"/>
	      <mass value="0.184"/>
	     <inertia
        izz="2.365E-05"
        ixy="-5.3771E-07"
        ixz="-1.6144E-06"
        iyy="0.00010469"
        iyz="8.3059E-08"
        ixx="0.00011187" />
	    </inertial>
	    <collision>
	      <origin rpy="0.000 0.000 0.000" xyz="0.000 0.000 0.000"/>
	      <geometry>
		<mesh filename="/home/sudharsan/Documents/notspot_sim_py/src/notspot_description/meshes/dae_files/R2_obj.dae"/>
	      </geometry>
	    </collision>
	  </link>
	  <!-- FL3 -->
	  <link name="FL3">
	    <visual>
	      <geometry>
		<mesh filename="/home/sudharsan/Documents/notspot_sim_py/src/notspot_description/meshes/dae_files/L3_obj.dae"/>
	      </geometry>
	    </visual>
	    <inertial>
	      <origin rpy="0.000 0.000 0.000" xyz="-0.00700 -0.000079 -0.08000"/>
	      <mass value="0.034"/>
	      <inertia
      	ixx = "1.800E-05"
		ixy = "2.279E-08"
		ixz = "5.988E-07"
		iyy = "1.793E-05"
		iyz = "-1.452E-06"
		izz = "1.211E-06"/>
	    </inertial>
	    <collision>
	      <origin rpy="0.000 0.000 0.000" xyz="0.000 0.000 0.000"/>
	      <geometry>
		<mesh filename="/home/sudharsan/Documents/notspot_sim_py/src/notspot_description/meshes/dae_files/L3_obj.dae"/>
	      </geometry>
	    </collision>
	  </link>
	  <!-- FR3 -->
	  <link name="FR3">
	    <visual>
	      <geometry>
		<mesh filename="/home/sudharsan/Documents/notspot_sim_py/src/notspot_description/meshes/dae_files/R3_obj.dae"/>
	      </geometry>
	    </visual>
	    <inertial>
	      <origin rpy="0.000 0.000 0.000" xyz="-0.00700 -0.000079 -0.08000"/>
	      <mass value="0.034"/>
	      <inertia
        izz="6.565E-07"
        ixy="6.8071E-07"
        ixz="-1.0503E-07"
        iyy="2.7257E-05"
        iyz="3.918E-09"
        ixx="2.7469E-05" />
	    </inertial>
	    <collision>
	      <origin rpy="0.000 0.000 0.000" xyz="0.000 0.000 0.000"/>
	      <geometry>
		<mesh filename="/home/sudharsan/Documents/notspot_sim_py/src/notspot_description/meshes/dae_files/R3_obj.dae"/>
	      </geometry>
	    </collision>
	  </link>
	  <!-- RL3 -->
	  <link name="RL3">
	    <visual>
	      <geometry>
		<mesh filename="/home/sudharsan/Documents/notspot_sim_py/src/notspot_description/meshes/dae_files/L3_obj.dae"/>
	      </geometry>
	    </visual>
	    <inertial>
	      <origin rpy="0.000 0.000 0.000" xyz="-0.00700 -0.000079 -0.08000"/>
	      <mass value="0.034"/>
	       <inertia
      	ixx = "1.800E-05"
		ixy = "2.279E-08"
		ixz = "5.988E-07"
		iyy = "1.793E-05"
		iyz = "-1.452E-06"
		izz = "1.211E-06"/>
	    </inertial>
	    <collision>
	      <origin rpy="0.000 0.000 0.000" xyz="0.000 0.000 0.000"/>
	      <geometry>
		<mesh filename="/home/sudharsan/Documents/notspot_sim_py/src/notspot_description/meshes/dae_files/L3_obj.dae"/>
	      </geometry>
	    </collision>
	  </link>
	  <!-- RR3 -->
	  <link name="RR3">
	    <visual>
	      <geometry>
		<mesh filename="/home/sudharsan/Documents/notspot_sim_py/src/notspot_description/meshes/dae_files/R3_obj.dae"/>
	      </geometry>
	    </visual>
	    <inertial>
	      <origin rpy="0.000 0.000 0.000" xyz="-0.00700 -0.000079 -0.08000"/>
	      <mass value="0.034"/>
	      <inertia
        izz="6.565E-07"
        ixy="6.8071E-07"
        ixz="-1.0503E-07"
        iyy="2.7257E-05"
        iyz="3.918E-09"
        ixx="2.7469E-05" />
	    </inertial>
	    <collision>
	      <origin rpy="0.000 0.000 0.000" xyz="0.000 0.000 0.000"/>
	      <geometry>
		<mesh filename="/home/sudharsan/Documents/notspot_sim_py/src/notspot_description/meshes/dae_files/R3_obj.dae"/>
	      </geometry>
	    </collision>
	  </link>
	  <!-- FL4 -->
	  <link name="FL4">
	    <visual>
	      <geometry>
		<sphere radius="0.001"/>
	      </geometry>
	    </visual>
	    <inertial>
	      <origin rpy="0.000 0.000 0.000" xyz="0.000 0.000 0.000"/>
	      <mass value="0.010"/>
	      <inertia
        izz="3.7713E-012"
        ixy="0"
        ixz="0"
        iyy="3.5422E-12"
        iyz="0"
        ixx="5.443E-012" />
	    </inertial>
	    <collision>
	      <origin rpy="0.000 0.000 0.000" xyz="0.000 0.000 0.000"/>
	      <geometry>
		<box size="0.011 0.011 0.011"/>
	      </geometry>
	    </collision>
	  </link>
	  <!-- FR4 -->
	  <link name="FR4">
	    <visual>
	      <geometry>
		<sphere radius="0.001"/>
	      </geometry>
	    </visual>
	    <inertial>
	      <origin rpy="0.000 0.000 0.000" xyz="0.000 0.000 0.000"/>
	      <mass value="0.010"/>
	      <inertia
        izz="3.7713E-012"
        ixy="0"
        ixz="0"
        iyy="3.5422E-12"
        iyz="0"
        ixx="5.443E-012" />
	    </inertial>
	    <collision>
	      <origin rpy="0.000 0.000 0.000" xyz="0.000 0.000 0.000"/>
	      <geometry>
		<box size="0.011 0.011 0.011"/>
	      </geometry>
	    </collision>
	  </link>
	  <!-- RL4 -->
	  <link name="RL4">
	    <visual>
	      <geometry>
		<sphere radius="0.001"/>
	      </geometry>
	    </visual>
	    <inertial>
	      <origin rpy="0.000 0.000 0.000" xyz="0.000 0.000 0.000"/>
	      <mass value="0.010"/>
	      <inertia
        izz="3.7713E-012"
        ixy="0"
        ixz="0"
        iyy="3.5422E-12"
        iyz="0"
        ixx="5.443E-012" />
	    </inertial>
	    <collision>
	      <origin rpy="0.000 0.000 0.000" xyz="0.000 0.000 0.000"/>
	      <geometry>
		<box size="0.011 0.011 0.011"/>
	      </geometry>
	    </collision>
	  </link>
	  <!-- RR4 -->
	  <link name="RR4">
	    <visual>
	      <geometry>
		<sphere radius="0.001"/>
	      </geometry>
	    </visual>
	    <inertial>
	      <origin rpy="0.000 0.000 0.000" xyz="0.000 0.000 0.000"/>
	      <mass value="0.010"/>
	       <inertia
        izz="3.7713E-012"
        ixy="0"
        ixz="0"
        iyy="3.5422E-12"
        iyz="0"
        ixx="5.443E-012" />
	    </inertial>
	    <collision>
	      <origin rpy="0.000 0.000 0.000" xyz="0.000 0.000 0.000"/>
	      <geometry>
		<box size="0.011 0.011 0.011"/>
	      </geometry>
	    </collision>
	  </link>
	  <!-- JOINTS REFERENCES -->
	  <!-- <joint dont_collapse="true" name="fl_ref" type="fixed">
	    <parent link="base_link"/>
	    <child link="hip_fl_ref"/>
	    <origin xyz="0.09170 0.05355 -0.00279"/>
	  </joint>
	  <joint dont_collapse="true" name="fr_ref" type="fixed">
	    <parent link="base_link"/>
	    <child link="hip_fr_ref"/>
	    <origin xyz="0.09170 -0.05355 -0.00279"/>
	  </joint>
	  <joint dont_collapse="true" name="bl_ref" type="fixed">
	    <parent link="base_link"/>
	    <child link="hip_bl_ref"/>
	    <origin xyz="-0.09170 0.05355 -0.00279"/>
	  </joint>
	  <joint dont_collapse="true" name="br_ref" type="fixed">
	    <parent link="base_link"/>
	    <child link="hip_br_ref"/>
	    <origin xyz="-0.09170 -0.05355 -0.00279"/>
	  </joint> -->
	  <!-- JOINTS -->
	  <joint name="FL1_joint" type="revolute">
	    <axis xyz="-1.000 0.000 0.000"/>
	    <limit effort="1.4" lower="-0.78540" upper="1.57080" velocity="1.04720"/>
	    <!-- <parent link="hip_fl_ref"/> -->
	    <parent link="base_link"/>
	    <child link="FL1"/>
	    <origin xyz="0.09170 0.05355 -0.00279"/>
	  </joint>
	  <joint name="FR1_joint" type="revolute">
	    <axis xyz="-1.000 0.000 0.000"/>
	    <limit effort="1.4" lower="-0.78540" upper="1.57080" velocity="1.04720"/>
	    <parent link="base_link"/>
	    <child link="FR1"/>
	    <origin xyz="0.09170 -0.05355 -0.00279"/>
	  </joint>
	  <joint name="RL1_joint" type="revolute">
	    <axis xyz="-1.000 0.000 0.000"/>
	    <limit effort="1.4" lower="-0.78540" upper="1.57080" velocity="1.04720"/>
	    <parent link="base_link"/>
	    <child link="RL1"/>
	    <origin xyz="-0.09170 0.05355 -0.00279"/>
	  </joint>
	  <joint name="RR1_joint" type="revolute">
	    <axis xyz="-1.000 0.000 0.000"/>
	    <limit effort="1.4" lower="-0.78540" upper="1.57080" velocity="1.04720"/>
	    <parent link="base_link"/>
	    <child link="RR1"/>
	    <origin xyz="-0.09170 -0.05355 -0.00279"/>
	  </joint>
	  <joint name="FL2_joint" type="revolute">
	    <axis xyz="0.000 1.000 0.000"/>
	    <limit effort="1.4" lower="0.00020" upper="2.35619" velocity="1.04720"/>
	    <parent link="FL1"/>
	    <child link="FL2"/>
	    <origin xyz="0.00000 0.03559 0.00020"/>
	  </joint>
	  <joint name="FR2_joint" type="revolute">
	    <axis xyz="0.000 1.000 0.000"/>
	    <limit effort="1.4" lower="0.00020" upper="2.35619" velocity="1.04720"/>
	    <parent link="FR1"/>
	    <child link="FR2"/>
	    <origin xyz="0.00000 -0.03559 0.00000"/>
	  </joint>
	  <joint name="RL2_joint" type="revolute">
	    <axis xyz="0.000 1.000 0.000"/>
	    <limit effort="1.4" lower="0.00020" upper="2.35619" velocity="1.04720"/>
	    <parent link="RL1"/>
	    <child link="RL2"/>
	    <origin xyz="0.00000 0.03559 0.00000"/>
	  </joint>
	  <joint name="RR2_joint" type="revolute">
	    <axis xyz="0.000 1.000 0.000"/>
	    <limit effort="1.4" lower="0.00000" upper="2.35619" velocity="1.04720"/>
	    <parent link="RR1"/>
	    <child link="RR2"/>
	    <origin xyz="0.00000 -0.03559 0.00000"/>
	  </joint>
	  <joint name="FL3_joint" type="revolute">
	    <axis xyz="0.000 1.000 0.000"/>
	    <limit effort="1.4" lower="-2.35619" upper="-0.52360" velocity="1.04720"/>
	    <parent link="FL2"/>
	    <child link="FL3"/>
	    <origin xyz="0.00000 0.01071 -0.09996" />
	  </joint>
	  <joint name="FR3_joint" type="revolute">
	    <axis xyz="0.000 1.000 0.000"/>
	    <limit effort="1.4" lower="-2.35619" upper="-0.52360" velocity="1.04720"/>
	    <parent link="FR2"/>
	    <child link="FR3"/>
	    <origin xyz="0.00000 -0.01071 -0.09996"/>
	  </joint>
	  <joint name="RL3_joint" type="revolute">
	    <axis xyz="0.000 1.000 0.000"/>
	    <limit effort="1.4" lower="-2.35619" upper="-0.52360" velocity="1.04720"/>
	    <parent link="RL2"/>
	    <child link="RL3"/>
	    <origin xyz="0.00000 0.01071 -0.09996"/>
	  </joint>
	  <joint name="RR3_joint" type="revolute">
	    <axis xyz="0.000 1.000 0.000"/>
	    <limit effort="1.4" lower="-2.35619" upper="-0.52360" velocity="1.04720"/>
	    <parent link="RR2"/>
	    <child link="RR3"/>
	    <origin xyz="0.00000 -0.01071 -0.09996" />
	  </joint>
	  <joint dont_collapse="true" name="FL4_joint" type="fixed">
	    <parent link="FL3"/>
	    <child link="FL4"/>
	    <origin xyz="0.00000 -0.00834 -0.10000"/>
	  </joint>
	  <joint dont_collapse="true" name="FR4_joint" type="fixed">
	    <parent link="FR3"/>
	    <child link="FR4"/>
	    <origin xyz="0.00000 0.00834 -0.10000"/>
	  </joint>
	  <joint dont_collapse="true" name="RL4_joint" type="fixed">
	    <parent link="RL3"/>
	    <child link="RL4"/>
	    <origin xyz="0.00000 -0.00834 -0.10000"/>
	  </joint>
	  <joint dont_collapse="true" name="RR4_joint" type="fixed">
	    <parent link="RR3"/>
	    <child link="RR4"/>
	    <origin xyz="0.00000 0.00834 -0.10000"/>
	  </joint>
	  <!-- ROS control plugin -->
	  <gazebo>
	    <plugin filename="libgazebo_ros_control.so" name="gazebo_ros_control">
	      <robotNamespace>notspot_controller</robotNamespace>
	      <!-- <robotParam>/notspot_description</robotParam> -->
	    </plugin>
	  </gazebo>
	  <!-- IMU sensor -->
	  <gazebo reference="base_link">
	    <gravity>true</gravity>
	    <sensor name="imu_sensor" type="imu">
	      <always_on>true</always_on>
	      <update_rate>100</update_rate>
	      <visualize>true</visualize>
	      <topic>__default_topic__</topic>
	      <plugin filename="libgazebo_ros_imu_sensor.so" name="imu_plugin">
		<topicName>notspot_imu/base_link_orientation</topicName>
		<bodyName>imu_link</bodyName>
		<updateRateHZ>15.0</updateRateHZ>
		<gaussianNoise>0.0</gaussianNoise>
		<xyzOffset>0 0 0</xyzOffset>
		<rpyOffset>0 0 0</rpyOffset>
		<frameName>base_link</frameName>
		<initialOrientationAsReference>false</initialOrientationAsReference>
	      </plugin>
	      <pose>0 0 0 0 0 0</pose>
	    </sensor>
	  </gazebo>
	  <!-- Joint state publisher plugin -->
	  <gazebo>
	    <plugin filename="libgazebo_ros_joint_state_publisher.so" name="joint_state_publisher">
	      <robotNamespace>notspot_gazebo</robotNamespace>
	      <jointName>FR1_joint,FR2_joint,FR3_joint,FL1_joint,FL2_joint,
		           FL3_joint,RR1_joint,RR2_joint,RR3_joint,RL1_joint,
		           RL2_joint,RL3_joint</jointName>
	      <updateRate>100</updateRate>
	    </plugin>
	  </gazebo>
	  <!-- TRANSMISSIONS -->
	  <transmission name="tran1">
	    <type>transmission_interface/SimpleTransmission</type>
	    <joint name="FR1_joint">
	      <hardwareInterface>hardware_interface/EffortJointInterface</hardwareInterface>
	    </joint>
	    <actuator name="motor1">
	      <hardwareInterface>hardware_interface/EffortJointInterface</hardwareInterface>
	      <mechanicalReduction>5</mechanicalReduction>
	    </actuator>
	  </transmission>
	  <transmission name="tran2">
	    <type>transmission_interface/SimpleTransmission</type>
	    <joint name="FR2_joint">
	      <hardwareInterface>hardware_interface/EffortJointInterface</hardwareInterface>
	    </joint>
	    <actuator name="motor2">
	      <hardwareInterface>hardware_interface/EffortJointInterface</hardwareInterface>
	      <mechanicalReduction>5</mechanicalReduction>
	    </actuator>
	  </transmission>
	  <transmission name="tran3">
	    <type>transmission_interface/SimpleTransmission</type>
	    <joint name="FR3_joint">
	      <hardwareInterface>hardware_interface/EffortJointInterface</hardwareInterface>
	    </joint>
	    <actuator name="motor3">
	      <hardwareInterface>hardware_interface/EffortJointInterface</hardwareInterface>
	      <mechanicalReduction>5</mechanicalReduction>
	    </actuator>
	  </transmission>
	  <transmission name="tran4">
	    <type>transmission_interface/SimpleTransmission</type>
	    <joint name="FL1_joint">
	      <hardwareInterface>hardware_interface/EffortJointInterface</hardwareInterface>
	    </joint>
	    <actuator name="motor4">
	      <hardwareInterface>hardware_interface/EffortJointInterface</hardwareInterface>
	      <mechanicalReduction>5</mechanicalReduction>
	    </actuator>
	  </transmission>
	  <transmission name="tran5">
	    <type>transmission_interface/SimpleTransmission</type>
	    <joint name="FL2_joint">
	      <hardwareInterface>hardware_interface/EffortJointInterface</hardwareInterface>
	    </joint>
	    <actuator name="motor5">
	      <hardwareInterface>hardware_interface/EffortJointInterface</hardwareInterface>
	      <mechanicalReduction>5</mechanicalReduction>
	    </actuator>
	  </transmission>
	  <transmission name="tran6">
	    <type>transmission_interface/SimpleTransmission</type>
	    <joint name="FL3_joint">
	      <hardwareInterface>hardware_interface/EffortJointInterface</hardwareInterface>
	    </joint>
	    <actuator name="motor6">
	      <hardwareInterface>hardware_interface/EffortJointInterface</hardwareInterface>
	      <mechanicalReduction>5</mechanicalReduction>
	    </actuator>
	  </transmission>
	  <transmission name="tran7">
	    <type>transmission_interface/SimpleTransmission</type>
	    <joint name="RR1_joint">
	      <hardwareInterface>hardware_interface/EffortJointInterface</hardwareInterface>
	    </joint>
	    <actuator name="motor7">
	      <hardwareInterface>hardware_interface/EffortJointInterface</hardwareInterface>
	      <mechanicalReduction>5</mechanicalReduction>
	    </actuator>
	  </transmission>
	  <transmission name="tran8">
	    <type>transmission_interface/SimpleTransmission</type>
	    <joint name="RR2_joint">
	      <hardwareInterface>hardware_interface/EffortJointInterface</hardwareInterface>
	    </joint>
	    <actuator name="motor8">
	      <hardwareInterface>hardware_interface/EffortJointInterface</hardwareInterface>
	      <mechanicalReduction>5</mechanicalReduction>
	    </actuator>
	  </transmission>
	  <transmission name="tran9">
	    <type>transmission_interface/SimpleTransmission</type>
	    <joint name="RR3_joint">
	      <hardwareInterface>hardware_interface/EffortJointInterface</hardwareInterface>
	    </joint>
	    <actuator name="motor9">
	      <hardwareInterface>hardware_interface/EffortJointInterface</hardwareInterface>
	      <mechanicalReduction>5</mechanicalReduction>
	    </actuator>
	  </transmission>
	  <transmission name="tran10">
	    <type>transmission_interface/SimpleTransmission</type>
	    <joint name="RL1_joint">
	      <hardwareInterface>hardware_interface/EffortJointInterface</hardwareInterface>
	    </joint>
	    <actuator name="motor10">
	      <hardwareInterface>hardware_interface/EffortJointInterface</hardwareInterface>
	      <mechanicalReduction>5</mechanicalReduction>
	    </actuator>
	  </transmission>
	  <transmission name="tran11">
	    <type>transmission_interface/SimpleTransmission</type>
	    <joint name="RL2_joint">
	      <hardwareInterface>hardware_interface/EffortJointInterface</hardwareInterface>
	    </joint>
	    <actuator name="motor11">
	      <hardwareInterface>hardware_interface/EffortJointInterface</hardwareInterface>
	      <mechanicalReduction>5</mechanicalReduction>
	    </actuator>
	  </transmission>
	  <transmission name="tran12">
	    <type>transmission_interface/SimpleTransmission</type>
	    <joint name="RL3_joint">
	      <hardwareInterface>hardware_interface/EffortJointInterface</hardwareInterface>
	    </joint>
	    <actuator name="motor12">
	      <hardwareInterface>hardware_interface/EffortJointInterface</hardwareInterface>
	      <mechanicalReduction>5</mechanicalReduction>
	    </actuator>
	  </transmission>
	  <!-- FR4 friction -->
	  <gazebo reference="FR4">
	    <mu1>1.0</mu1>
	    <mu2>1.0</mu2>
	    <minDepth>0.0002</minDepth>
	    <kp value="1000000.0"/>
	    <kd value="100.0"/>
	  </gazebo>
	  <!-- FL4 friction -->
	  <gazebo reference="FL4">
	    <mu1>1.0</mu1>
	    <mu2>1.0</mu2>
	    <minDepth>0.0002</minDepth>
	    <kp value="1000000.0"/>
	    <kd value="100.0"/>
	  </gazebo>
	  <!-- RR4 friction -->
	  <gazebo reference="RR4">
	    <mu1>1.0</mu1>
	    <mu2>1.0</mu2>
	    <minDepth>0.0002</minDepth>
	    <kp value="1000000.0"/>
	    <kd value="100.0"/>
	  </gazebo>
	  <!-- RL4 friction -->
	  <gazebo reference="RL4">
	    <mu1>1.0</mu1>
	    <mu2>1.0</mu2>
	    <minDepth>0.0002</minDepth>
	    <kp value="1000000.0"/>
	    <kd value="100.0"/>
	  </gazebo>
</robot>